Traceback (most recent call last):                                             
Liver Validation Complete: Loss: 0.1277, Dice: 0.9012
Right_kidney Validation Complete: Loss: 0.0332, Dice: 0.9619
Spleen Validation Complete: Loss: 0.0548, Dice: 0.9499
Pancreas Validation Complete: Loss: 0.2123, Dice: 0.7595
Aorta Validation Complete: Loss: 0.0462, Dice: 0.9453
Ivc Validation Complete: Loss: 0.0792, Dice: 0.9092
Right_adrenal_gland Validation Complete: Loss: 0.1881, Dice: 0.7738
Left_adrenal_gland Validation Complete: Loss: 0.1460, Dice: 0.8308
Gallbladder Validation Complete: Loss: 0.1191, Dice: 0.8806
Esophagus Validation Complete: Loss: 0.1142, Dice: 0.8531
Stomach Validation Complete: Loss: 0.1756, Dice: 0.8210
Left_kidney Validation Complete: Loss: 0.0281, Dice: 0.9685
Time: 20250619-1442, train_Loss: 0.05560874919744033, train_accuracy : 0.9351560139702871
Epoch 2/100
  File "/home/uqz9095/miniconda3/lib/python3.13/site-packages/torch/serialization.py", line 944, in save
    _save(
    ~~~~~^
        obj,
        ^^^^
    ...<3 lines>...
        _disable_byteorder_record,
        ^^^^^^^^^^^^^^^^^^^^^^^^^^
    )
    ^
  File "/home/uqz9095/miniconda3/lib/python3.13/site-packages/torch/serialization.py", line 1216, in _save
    zip_file.write_record(name, storage, num_bytes)
    ~~~~~~~~~~~~~~~~~~~~~^^^^^^^^^^^^^^^^^^^^^^^^^^
RuntimeError: [enforce fail at inline_container.cc:815] . PytorchStreamWriter failed writing file data/1015: file write failed

During handling of the above exception, another exception occurred:

Traceback (most recent call last):
  File "/gpfs/home/uqz9095/OMT-SAM/train_one_gpu_new_Step3.py", line 505, in <module>
    main()
    ~~~~^^
  File "/gpfs/home/uqz9095/OMT-SAM/train_one_gpu_new_Step3.py", line 457, in main
    torch.save(checkpoint, join(model_save_path, "medsam_model_latest.pth"))
    ~~~~~~~~~~^^^^^^^^^^^^^^^^^^^^^^^^^^^^^^^^^^^^^^^^^^^^^^^^^^^^^^^^^^^^^^
  File "/home/uqz9095/miniconda3/lib/python3.13/site-packages/torch/serialization.py", line 943, in save
    with _open_zipfile_writer(f) as opened_zipfile:
         ~~~~~~~~~~~~~~~~~~~~^^^
  File "/home/uqz9095/miniconda3/lib/python3.13/site-packages/torch/serialization.py", line 784, in __exit__
    self.file_like.write_end_of_file()
    ~~~~~~~~~~~~~~~~~~~~~~~~~~~~~~~~^^
RuntimeError: [enforce fail at inline_container.cc:626] . unexpected pos 34309504 vs 34309396
